Workbook

Sheet ANNEX F
D1: ANNEX F
A3: Name of Facility:
A4: Address :
A5: PhilHealth Accreditation Number:
A7: LIST OF CLAIM SERIES EVALUATED AS NO RECIEVABLE AUTHORIZED FOR ARCHIVING
A8: Claims Series Number | B8: Patient's Name | C8: Confinement Period | D8: Claim Amount
A9: 2022
A10: 1.
A11: 2.
A12: 3.
A13: n.....
A14: 2021
A15: 1.
A16: 2.
A17: 3.
A18: n.....
A19: 2020
A20: 1.
A21: 2.
A22: 3.
A23: n.....
A24: 2019
A25: 1.
A26: 2.
A27: 3.
A28: n.....
A29: 2018
A30: 1.
A31: 2.
A32: 3.
A33: n.....
A34: 2017
A35: 1.
A36: 2.
A37: 3.
A38: n.....
A39: 2016
A40: 1.
A41: 2.
A42: 3.
...

Sheet ANNEX B
A1: GEN. TRIAS CHO ANIMAL BITE TREATMENT CENTER | N1: ANNEX B
A2: B41031323
A3: HOSPITAL RD., BRGY. PINAGTIPUNAN, CITY OF GENERAL TRIAS, CAVITE
A5: Report of Unsubmitted Claims - IBNR
A6: As of ____________________________
A8: Item No. | B8: Claims Code/Reference Number | C8: Patient Name | F8: Member Name | I8: Member's PIN | J8: Date of Admission (mm/dd/yyyy) | K8: Dale of Discharged (mm/dd/yyyy) | L8: Case Rate/ Claim amount | M8: ICD 10/RVS code | N8: Claim Status
C9: Surname | D9: First Name | E9: Middle Name | F9: Surname | G9: First Name | H9: Middle Name
A10: 1
A11: 2
A12: 3
A13: 4
A14: 5
A15: 6
A16: 7
A17: 8
A18: 9
A19: 10
A20: 11
A21: 12
... A29: 20
K30: TOTAL | L30: =SUM(L10:L29) -> 0
A31: Prepared by: | E31: Certified Complete and Accurate by: | K31: Approved by:
A33: =Names!A1 -> LUIS P. BROAS, RN, RPh, MAN, CAE | E33: =Names!A4 -> DR. EMMANUEL D. MAGSINO | K33: =Names!A7 -> JONATHAN P. LUSECO, RN, MD
A34: =Names!A2 -> Nurse III-CESU Designated Head | E34: =Names!A5 -> City Accountant I | K34: =Names!A8 -> City Health Officer II

Sheet ANNEX C
A1: ='ANNEX B'!A1 -> GEN. TRIAS CHO ANIMAL BITE TREATMENT CENTER | Q1: ANNEX C
A2: ='ANNEX B'!A2 -> B41031323
A3: ='ANNEX B'!A3 -> HOSPITAL RD., BRGY. PINAGTIPUNAN, CITY OF GENERAL TRIAS, CAVITE
A5: REPORT OF UNPAID CLAIMS - ACCOUNTS RECEIVABLE
A6: As of __________________________________ | B6: ='ANNEX B'!B6 -> 0
A8: Item No. | B8: YEAR (start from current) | C8: Claim Series Number | D8: Patient Name | G8: Member Name | J8: Member’s PIN | K8: Date of Admission (mm/dd/yyy) | L8: Date of Discharged (mm/dd/yyyy) | M8: Date of Filed (mm/dd/yyyy) | N8: Date of Refiled (mm/dd/yyyy) | O8: Case Rate/ Claim amount | P8: ICD 10/RVS code | Q8: *Claim Status
D9: Surname | E9: First Name | F9: Middle Name | G9: Surname | H9: First Name | I9: Middle Name
A10: 1
A11: 2
A12: 3
A13: 4
A14: 5
A15: 6
A16: 7
A17: 8
A18: 9
A19: 10
A20: 11
A21: 12
... A29: 20
A30: * Claim Status : In process, Return to Hospital (RTH), Denied, Filed under MR or under Appeal | N30: TOTAL | O30: =SUM(O10:O29) -> 0
A32: Prepared by: | F32: Certified Complete and Accurate by: | K32: Approved by:
A34: =Names!A1 -> LUIS P. BROAS, RN, RPh, MAN, CAE | F34: =Names!A4 -> DR. EMMANUEL D. MAGSINO | K34: =Names!A7 -> JONATHAN P. LUSECO, RN, MD
A35: =Names!A2 -> Nurse III-CESU Designated Head | F35: =Names!A5 -> City Accountant I | K35: =Names!A8 -> City Health Officer II

Sheet ANNEX D_CRC
A1: ='ANNEX B'!A1 -> GEN. TRIAS CHO ANIMAL BITE TREATMENT CENTER | N1: ANNEX D
A2: ='ANNEX B'!A2 -> B41031323
A3: ='ANNEX B'!A3 -> HOSPITAL RD., BRGY. PINAGTIPUNAN, CITY OF GENERAL TRIAS, CAVITE
A5: Report of Protested Claims to Claims Review Committee (CRC)
A6: As of ____________________________ | B6: ='ANNEX B'!B6 -> 0
A8: Item No. | B8: Claims Code/ Reference Number | C8: Patient Name | F8: Member Name | I8: Member's PIN | J8: Date of Admission (mm/dd/yyyy) | K8: Dale of Discharged (mm/dd/yyyy) | L8: Case Rate/ Claim amount | M8: ICD 10/RVS code | N8: Date of Filing / Protest
C9: Surname | D9: First Name | E9: Middle Name | F9: Surname | G9: First Name | H9: Middle Name
A10: 1
A11: 2
A12: 3
A13: 4
A14: 5
A15: 6
A16: 7
A17: 8
A18: 9
A19: 10
A20: 11
A21: 12
... A29: 20
K30: TOTAL | L30: =SUM(L10:L29) -> 0
A31: Prepared by: | E31: Certified Complete and Accurate by: | K31: Approved by:
A33: =Names!A1 -> LUIS P. BROAS, RN, RPh, MAN, CAE | E33: =Names!A4 -> DR. EMMANUEL D. MAGSINO | K33: =Names!A7 -> JONATHAN P. LUSECO, RN, MD
A34: =Names!A2 -> Nurse III-CESU Designated Head | E34: =Names!A5 -> City Accountant I | K34: =Names!A8 -> City Health Officer II

Sheet Names
A1: LUIS P. BROAS, RN, RPh, MAN, CAE
A2: Nurse III-CESU Designated Head
A4: DR. EMMANUEL D. MAGSINO
A5: City Accountant I
A7: JONATHAN P. LUSECO, RN, MD
A8: City Health Officer II

Sheet ANNEX E
B1: ANNEX E
A3: Name of Facility:
A4: Address:
A5: PhilHealth Accreditation Number:
A7: AUTHORITY TO ARCHIVE CLAIMS WITH NO TAG-NO RECEIVABLE CLAIMS
A8: YEAR | B8: Count of Claims Existing on the Calendar Years Certified by Health Facility with "Non-Receivables"
A9: 1995
A10: 1996
A11: 1997
A12: 1998
A13: 1999
A14: 2000
A15: 2001
A16: 2002
A17: 2003
A18: 2004
A19: 2005
A20: 2006
... A36: 2022
A38: Prepared by: | B38: Recommending Approval:
A41: BAS Head | B41: HCDMD Head
A45: FMS Head | B45: MSD Head
A48: Approved by:
A50: RVP/Branch Manager
A51: (Signature over printed name)
